distributed.nanny - INFO -         Start Nanny at: 'tcp://153.5.72.24:39575'
distributed.nanny - INFO -         Start Nanny at: 'tcp://153.5.72.24:43803'
distributed.nanny - INFO - Closing Nanny at 'tcp://153.5.72.24:39575'
distributed.nanny - INFO - Closing Nanny at 'tcp://153.5.72.24:43803'
distributed.nanny - WARNING - Worker process still alive after 0 seconds, killing
distributed.nanny - WARNING - Worker process still alive after 0 seconds, killing
distributed.dask_worker - INFO - End worker
Traceback (most recent call last):
  File "/cvmfs/sling.si/modules/el7/software/Anaconda3/2020.11/lib/python3.8/site-packages/distributed/core.py", line 295, in _
    await asyncio.wait_for(self.start(), timeout=timeout)
  File "/cvmfs/sling.si/modules/el7/software/Anaconda3/2020.11/lib/python3.8/asyncio/tasks.py", line 490, in wait_for
    raise exceptions.TimeoutError()
asyncio.exceptions.TimeoutError

During handling of the above exception, another exception occurred:

Traceback (most recent call last):
  File "/cvmfs/sling.si/modules/el7/software/Anaconda3/2020.11/lib/python3.8/runpy.py", line 194, in _run_module_as_main
    return _run_code(code, main_globals, None,
  File "/cvmfs/sling.si/modules/el7/software/Anaconda3/2020.11/lib/python3.8/runpy.py", line 87, in _run_code
    exec(code, run_globals)
  File "/cvmfs/sling.si/modules/el7/software/Anaconda3/2020.11/lib/python3.8/site-packages/distributed/cli/dask_worker.py", line 460, in <module>
    go()
  File "/cvmfs/sling.si/modules/el7/software/Anaconda3/2020.11/lib/python3.8/site-packages/distributed/cli/dask_worker.py", line 456, in go
    main()
  File "/cvmfs/sling.si/modules/el7/software/Anaconda3/2020.11/lib/python3.8/site-packages/click/core.py", line 829, in __call__
    return self.main(*args, **kwargs)
  File "/cvmfs/sling.si/modules/el7/software/Anaconda3/2020.11/lib/python3.8/site-packages/click/core.py", line 782, in main
    rv = self.invoke(ctx)
  File "/cvmfs/sling.si/modules/el7/software/Anaconda3/2020.11/lib/python3.8/site-packages/click/core.py", line 1066, in invoke
    return ctx.invoke(self.callback, **ctx.params)
  File "/cvmfs/sling.si/modules/el7/software/Anaconda3/2020.11/lib/python3.8/site-packages/click/core.py", line 610, in invoke
    return callback(*args, **kwargs)
  File "/cvmfs/sling.si/modules/el7/software/Anaconda3/2020.11/lib/python3.8/site-packages/distributed/cli/dask_worker.py", line 442, in main
    loop.run_sync(run)
  File "/cvmfs/sling.si/modules/el7/software/Anaconda3/2020.11/lib/python3.8/site-packages/tornado/ioloop.py", line 532, in run_sync
    return future_cell[0].result()
  File "/cvmfs/sling.si/modules/el7/software/Anaconda3/2020.11/lib/python3.8/site-packages/distributed/cli/dask_worker.py", line 436, in run
    await asyncio.gather(*nannies)
  File "/cvmfs/sling.si/modules/el7/software/Anaconda3/2020.11/lib/python3.8/asyncio/tasks.py", line 684, in _wrap_awaitable
    return (yield from awaitable.__await__())
  File "/cvmfs/sling.si/modules/el7/software/Anaconda3/2020.11/lib/python3.8/site-packages/distributed/core.py", line 299, in _
    raise TimeoutError(
asyncio.exceptions.TimeoutError: Nanny failed to start in 120 seconds
distributed.process - INFO - reaping stray process <SpawnProcess name='Dask Worker process (from Nanny)' pid=1280406 parent=1257774 started daemon>
distributed.process - INFO - reaping stray process <SpawnProcess name='Dask Worker process (from Nanny)' pid=1280404 parent=1257774 started daemon>
Exception in thread AsyncProcess Dask Worker process (from Nanny) watch process join:
Traceback (most recent call last):
  File "/cvmfs/sling.si/modules/el7/software/Anaconda3/2020.11/lib/python3.8/threading.py", line 932, in _bootstrap_inner
